Workbook

Sheet Summary
A1: HSFP 1:50 Test Matrix – Summary
A2: Target site: ~200 mi west of Seattle (deep Pacific, NDBC 46005 climate). Draft for TEAMER / HWRL scoping.
A4: Phase | B4: Configurations | C4: Decay runs | D4: Regular runs | E4: Irregular runs | F4: Special runs | G4: Total runs | H4: Tank hours | I4: Tank days
A5: Phase 1 – Individual buoys | B5: =COUNTIF(Configurations!$A$5:$A$19,1) -> 5 | C5: =SUMIFS(Configurations!$J$5:$J$19,Configurations!$A$5:$A$19,1) -> 30 | D5: =SUMIFS(Configurations!$K$5:$K$19,Configurations!$A$5:$A$19,1) -> 111 | E5: =SUMIFS(Configurations!$L$5:$L$19,Configurations!$A$5:$A$19,1) -> 30 | F5: =SUMIFS(Configurations!$I$5:$I$19,Configurations!$A$5:$A$19,1) -> 21 | G5: =SUMIFS(Configurations!$M$5:$M$19,Configurations!$A$5:$A$19,1) -> 192 | H5: =SUMIFS(Configurations!$N$5:$N$19,Configurations!$A$5:$A$19,1) -> 38.555273 | I5: =H5/Inputs!$B$24 -> 6.4258788
A6: Phase 2 – Buoy clusters | B6: =COUNTIF(Configurations!$A$5:$A$19,2) -> 4 | C6: =SUMIFS(Configurations!$J$5:$J$19,Configurations!$A$5:$A$19,2) -> 27 | D6: =SUMIFS(Configurations!$K$5:$K$19,Configurations!$A$5:$A$19,2) -> 111 | E6: =SUMIFS(Configurations!$L$5:$L$19,Configurations!$A$5:$A$19,2) -> 30 | F6: =SUMIFS(Configurations!$I$5:$I$19,Configurations!$A$5:$A$19,2) -> 12 | G6: =SUMIFS(Configurations!$M$5:$M$19,Configurations!$A$5:$A$19,2) -> 180 | H6: =SUMIFS(Configurations!$N$5:$N$19,Configurations!$A$5:$A$19,2) -> 36.505273 | I6: =H6/Inputs!$B$24 -> 6.0842121
A7: Phase 3 – Full platform | B7: =COUNTIF(Configurations!$A$5:$A$19,3) -> 6 | C7: =SUMIFS(Configurations!$J$5:$J$19,Configurations!$A$5:$A$19,3) -> 27 | D7: =SUMIFS(Configurations!$K$5:$K$19,Configurations!$A$5:$A$19,3) -> 144 | E7: =SUMIFS(Configurations!$L$5:$L$19,Configurations!$A$5:$A$19,3) -> 45 | F7: =SUMIFS(Configurations!$I$5:$I$19,Configurations!$A$5:$A$19,3) -> 14 | G7: =SUMIFS(Configurations!$M$5:$M$19,Configurations!$A$5:$A$19,3) -> 230 | H7: =SUMIFS(Configurations!$N$5:$N$19,Configurations!$A$5:$A$19,3) -> 54.060164 | I7: =H7/Inputs!$B$24 -> 9.0100274
A8: Total | B8: =SUM(B5:B7) -> 15 | C8: =SUM(C5:C7) -> 84 | D8: =SUM(D5:D7) -> 366 | E8: =SUM(E5:E7) -> 105 | F8: =SUM(F5:F7) -> 47 | G8: =SUM(G5:G7) -> 602 | H8: =SUM(H5:H7) -> 129.12071 | I8: =SUM(I5:I7) -> 21.520118
A10: By facility
A11: Facility | B11: Configurations | C11: Decay runs | D11: Regular runs | E11: Irregular runs | F11: Special runs | G11: Total runs | H11: Tank hours | I11: Tank days
A12: Large Wave Flume (LWF) | B12: =COUNTIF(Configurations!$D$5:$D$19,"LWF") -> 13 | C12: =SUMIFS(Configurations!$J$5:$J$19,Configurations!$D$5:$D$19,"LWF") -> 84 | D12: =SUMIFS(Configurations!$K$5:$K$19,Configurations!$D$5:$D$19,"LWF") -> 315 | E12: =SUMIFS(Configurations!$L$5:$L$19,Configurations!$D$5:$D$19,"LWF") -> 90 | F12: =SUMIFS(Configurations!$I$5:$I$19,Configurations!$D$5:$D$19,"LWF") -> 41 | G12: =SUMIFS(Configurations!$M$5:$M$19,Configurations!$D$5:$D$19,"LWF") -> 530 | H12: =SUMIFS(Configurations!$N$5:$N$19,Configurations!$D$5:$D$19,"LWF") -> 108.485 | I12: =H12/Inputs!$B$24 -> 18.080833
A13: Directional Wave Basin (DWB) | B13: =COUNTIF(Configurations!$D$5:$D$19,"DWB") -> 2 | C13: =SUMIFS(Configurations!$J$5:$J$19,Configurations!$D$5:$D$19,"DWB") -> 0 | D13: =SUMIFS(Configurations!$K$5:$K$19,Configurations!$D$5:$D$19,"DWB") -> 51 | E13: =SUMIFS(Configurations!$L$5:$L$19,Configurations!$D$5:$D$19,"DWB") -> 15 | F13: =SUMIFS(Configurations!$I$5:$I$19,Configurations!$D$5:$D$19,"DWB") -> 6 | G13: =SUMIFS(Configurations!$M$5:$M$19,Configurations!$D$5:$D$19,"DWB") -> 72 | H13: =SUMIFS(Configurations!$N$5:$N$19,Configurations!$D$5:$D$19,"DWB") -> 20.635712 | I13: =H13/Inputs!$B$24 -> 3.4392854
A15: Key points (confirm with HWRL – Pedro Lomonaco):
A16: • Site depth (~2,500 m) cannot be reproduced at 1:50. LWF at 2.74 m (137 m FS) makes waves ≤13 s fully deep-water and 14–20 s near-deep (kd ≈ 1.5–2.9); it also keeps the published 1.8 m wave-height capability.
A17: • Phase 3 baseline moved to the LWF: slender spars give low solid blockage, and the flume gives the deeper depth. The DWB (68 m FS) is used only for oblique headings and short-crested seas.
A18: • Side-wall effects: cross-flume standing modes at ~7.7, 8.9, 10.9 and 15.5 s FS (see Inputs; 7.7 and 10.9 s are the symmetric modes most likely excited). Install a cross-flume wave-gauge pair and keep the model centred.
A19: • Moorings: a ~2,500 m-deep site implies taut/synthetic moorings. The model needs a truncated mooring with equivalent horizontal stiffness – document the method.
A20: • Extremes from NDBC 46005: 10/25/50/100-yr Hs = 12.4 / 13.6 / 14.3 / 15.0 m; winter mean Hs 3.6–3.8 m, Tp ~12 s; storm Tp 12.5–20 s. Tp for extremes is assumed.
A21: • Tow tests: 1–8 kn FS → 0.07–0.58 m/s model. Confirm tow method with HWRL.
A22: Sequence per configuration: free decay → regular sweep (s1 first) → irregular operational → extremes/survival.
A23: References: ITTC 7.5-02-07-03.1 (floating offshore platform experiments); IEC TS 62600-103 (WEC testing); DNV-RP-C205 (environmental conditions & loads).
A24: Sources: teamer-us.org/facility/hinsdale-osu ; engineering.oregonstate.edu/facilities/wave-lab/facilities/directional-wave-basin ; Oregon DLCD (2000) Analyses of Extreme Waves and Water Levels (oregon.gov/lcd/Publications/Analysis_ExtremeWaves_WaterLevels_2000.pdf) ; Ruggiero, Komar & Allen (2010) Coastal Engineering 57, doi:10.1016/j.coastaleng.2009.12.005
A26: Legend: blue text on yellow = editable input; black = formula. Edit Inputs, wave sets (Y/N), sea states and configurations; totals update automatically.

Sheet Inputs
A1: HSFP 1:50 Test Matrix – Inputs & Assumptions
A2: Blue text on yellow = editable input. Black = formula. Confirm facility values with HWRL staff.
A3: Parameter | B3: Value | C3: Unit | D3: Source / note
A4: Geometric scale factor λ (full / model) | B4: 50 | C4: – | D4: HSFP summary (1/50 scale model)
A5: Target site | B5: ~200 mi W of Seattle | C5: – | D5: User-specified. ≈47.6°N, 127–128°W, Cascadia Basin (seaward of the continental slope)
A6: Site water depth, full scale (approx.) | B6: 2500 | C6: m | D6: APPROXIMATE – Cascadia Basin abyssal depths ~2,500–2,900 m; verify with NOAA bathymetry. Deep water for all test periods.
A7: LWF test water depth (model) | B7: 2.74 | C7: m | D7: Recommended: deepest depth with published high wave capability (1.8 m @ 2.74 m). Site depth cannot be reproduced at 1:50.
A8: LWF equivalent full-scale depth | B8: =B7*B4 -> 137 | C8: m | D8: Waves ≤ ~13 s are fully deep-water at this depth; 14–20 s are near-deep (kd ≈ 1.5–2.9)
A9: DWB water depth (model) | B9: 1.36 | C9: m | D9: OSU DWB page: max water depth 1.36 m
A10: DWB equivalent full-scale depth | B10: =B9*B4 -> 68 | C10: m | D10: Long-period waves are intermediate-depth here – use DWB only for heading / short-crested tests
A11: LWF max regular wave height (model) | B11: 1.8 | C11: m | D11: TEAMER: 1.8 m at 2.74 m depth. Long-period stroke limit may be lower – confirm with HWRL
A12: DWB max regular wave height (model) | B12: 0.8 | C12: m | D12: TEAMER/OSU: ~0.8 m at 1.37 m depth
A13: Regular wave steepness level 1 (H/L) – linear | B13: 0.016666667 | C13: – | D13: Linear RAO level
A14: Regular wave steepness level 2 (H/L) | B14: 0.033333333 | C14: – | D14: Moderate – linearity check
A15: Regular wave steepness level 3 (H/L) – steep | B15: 0.066666667 | C15: – | D15: Nonlinear / steep
A16: Regular waves recorded per run | B16: 30 | C16: waves | D16: Assumed; steady-state window before reflections
A17: Ramp-up / reflection-free overhead per run | B17: 60 | C17: s | D17: Assumed
A18: Wait between runs – LWF | B18: 6 | C18: min | D18: ASSUMPTION – confirm with HWRL
A19: Wait between runs – DWB | B19: 10 | C19: min | D19: ASSUMPTION – basin settles slower; confirm with HWRL
A20: Irregular sea-state duration, full scale | B20: 3 | C20: hr | D20: ≥3 hr full scale per ITTC/DNV practice
A21: Free-decay run length | B21: 2 | C21: min | D21: Assumed
A22: Free-decay repeats per DOF | B22: 3 | C22: – | D22: Assumed
... A24: Effective tank hours per day | B24: 6 | C24: hr | D24: Assumed (excludes setup, calibration, configuration changes)
A25: Gravity g | B25: 9.81 | C25: m/s²
A26: Platform footprint, model | B26: 2.4 | C26: m | D26: HSFP summary (~2.4 m square; slender spars, low solid blockage)
A27: Platform footprint, full scale | B27: =B26*B4 -> 120 | C27: m
A28: Minimum comfortable wavemaker period (model) | B28: 0.7 | C28: s | D28: ASSUMPTION – flags periods below this for HWRL review
A29: Time scale factor √λ | B29: =SQRT(B4) -> 7.0710678 | C29: – | D29: Froude: T_model = T_full / √λ
A30: Force scale factor (λ³ × ρ_sea/ρ_fresh) | B30: =B4^3*1.025 -> 128125 | C30: – | D30: Model tested in fresh water
A31: LWF width | B31: 3.7 | C31: m | D31: TEAMER: LWF 104 m × 3.7 m × 4.6 m
A32: Cross-mode flag window (± full-scale period) | B32: 0.5 | C32: s | D32: Regular periods within this window of a flume cross-mode are flagged
A35: LWF transverse (cross-flume) standing-wave modes at LWF test depth
A36: Mode n (wavelength = 2·width / n) | B36: T model (s) | C36: T full (s) | D36: Excitation for a centred model in head seas
A37: 1 | B37: =2*PI()/SQRT(Inputs!$B$25*(2*PI()/(2*Inputs!$B$31/A37))*TANH((2*PI()/(2*Inputs!$B$31/A37))*Inputs!$B$7)) -> 2.1979192 | C37: =B37*Inputs!$B$29 -> 15.541636 | D37: Antisymmetric – weakly excited if model is centred and aligned
A38: 2 | B38: =2*PI()/SQRT(Inputs!$B$25*(2*PI()/(2*Inputs!$B$31/A38))*TANH((2*PI()/(2*Inputs!$B$31/A38))*Inputs!$B$7)) -> 1.539557 | C38: =B38*Inputs!$B$29 -> 10.886312 | D38: Symmetric – can be excited by scattered/radiated waves; place cross-flume gauges
A39: 3 | B39: =2*PI()/SQRT(Inputs!$B$25*(2*PI()/(2*Inputs!$B$31/A39))*TANH((2*PI()/(2*Inputs!$B$31/A39))*Inputs!$B$7)) -> 1.2569298 | C39: =B39*Inputs!$B$29 -> 8.8878362 | D39: Antisymmetric – weakly excited if model is centred and aligned
A40: 4 | B40: =2*PI()/SQRT(Inputs!$B$25*(2*PI()/(2*Inputs!$B$31/A40))*TANH((2*PI()/(2*Inputs!$B$31/A40))*Inputs!$B$7)) -> 1.0885322 | C40: =B40*Inputs!$B$29 -> 7.6970853 | D40: Symmetric – can be excited by scattered/radiated waves; place cross-flume gauges
A43: Tow-speed conversion (horizontal transport tests)
A44: Full-scale tow speed (knots) | B44: Model speed (m/s)
A45: 1 | B45: =A45*0.5144/Inputs!$B$29 -> 0.072747146
...

Sheet Regular_Waves
A1: Regular Wave Set (RAO sweep)
A2: Heights set by steepness × deep-water wavelength (site is deep). Mark Y/N for Full and Reduced sets. Fill natural-period rows after free-decay tests.
A4: T full (s) | B4: T model (s) | C4: L0 deep (m, FS) | D4: L at LWF depth (m, FS) | E4: k·d at LWF depth | F4: Depth regime in LWF | G4: L at DWB depth (m, FS) | H4: L0 / footprint | I4: H s1 FS (m) | J4: H s1 model (m) | K4: H s2 FS (m) | L4: H s2 model (m) | M4: H s3 FS (m) | N4: H s3 model (m) | O4: Levels feasible LWF | P4: Levels feasible DWB | Q4: Full set (Y/N) | R4: Reduced set (Y/N) | S4: Run time (min, model) | T4: Flags / notes
A5: 4 | B5: =IF(A5="","",A5/SQRT(Inputs!$B$4)) -> 0.56568542 | C5: =IF(A5="","",Inputs!$B$25*A5^2/(2*PI())) -> 24.98096 | D5: =IF(A5="","",C5*TANH((2*PI()*Inputs!$B$8/C5)^0.75)^(2/3)) -> 24.98096 | E5: =IF(A5="","",2*PI()*Inputs!$B$8/D5) -> 34.458099 | F5: =IF(A5="","",IF(E5>=PI(),"Deep",IF(E5>=PI()/10,"Near-deep / intermediate","Shallow"))) -> Deep | G5: =IF(A5="","",C5*TANH((2*PI()*Inputs!$B$10/C5)^0.75)^(2/3)) -> 24.980958 | H5: =IF(A5="","",C5/Inputs!$B$27) -> 0.20817467 | I5: =IF(A5="","",C5*Inputs!$B$13) -> 0.41634933 | J5: =IF(A5="","",I5/Inputs!$B$4) -> 0.0083269866 | K5: =IF(A5="","",C5*Inputs!$B$14) -> 0.83269866 | L5: =IF(A5="","",K5/Inputs!$B$4) -> 0.016653973 | M5: =IF(A5="","",C5*Inputs!$B$15) -> 1.6653973 | N5: =IF(A5="","",M5/Inputs!$B$4) -> 0.033307946 | O5: =IF(A5="",0,(J5<=Inputs!$B$11)+(L5<=Inputs!$B$11)+(N5<=Inputs!$B$11)) -> 3 | P5: =IF(A5="",0,(J5<=Inputs!$B$12)+(L5<=Inputs!$B$12)+(N5<=Inputs!$B$12)) -> 3 | Q5: Y | R5: N | S5: =IF(A5="",0,(Inputs!$B$17+Inputs!$B$16*B5)/60) -> 1.2828427 | T5: =IF(A5="","Short-period limit – check wavemaker quality",IF(B5<Inputs!$B$28,"Below min comfortable wavemaker period. ","")&IF(OR(ABS(A5-Inputs!$C$38)<=Inputs!$B$32,ABS(A5-Inputs!$C$40)<=Inputs!$B$32),"Near symmetric flume cross-mode – check cross-flume gauges. ","")&IF(OR(ABS(A5-Inputs!$C$37)<=Inputs!$B$32,ABS(A5-Inputs!$C$39)<=Inputs!$B$32),"Near antisymmetric cross-mode – verify model centred. ","")&"Short-period limit – check wavemaker quality") -> Below min comfortable wavemaker period. Short-period limit – check wavemaker quality
A6: 5 | B6: =IF(A6="","",A6/SQRT(Inputs!$B$4)) -> 0.70710678 | C6: =IF(A6="","",Inputs!$B$25*A6^2/(2*PI())) -> 39.03275 | D6: =IF(A6="","",C6*TANH((2*PI()*Inputs!$B$8/C6)^0.75)^(2/3)) -> 39.03275 | E6: =IF(A6="","",2*PI()*Inputs!$B$8/D6) -> 22.053183 | F6: =IF(A6="","",IF(E6>=PI(),"Deep",IF(E6>=PI()/10,"Near-deep / intermediate","Shallow"))) -> Deep | G6: =IF(A6="","",C6*TANH((2*PI()*Inputs!$B$10/C6)^0.75)^(2/3)) -> 39.032441 | H6: =IF(A6="","",C6/Inputs!$B$27) -> 0.32527291 | I6: =IF(A6="","",C6*Inputs!$B$13) -> 0.65054583 | J6: =IF(A6="","",I6/Inputs!$B$4) -> 0.013010917 | K6: =IF(A6="","",C6*Inputs!$B$14) -> 1.3010917 | L6: =IF(A6="","",K6/Inputs!$B$4) -> 0.026021833 | M6: =IF(A6="","",C6*Inputs!$B$15) -> 2.6021833 | N6: =IF(A6="","",M6/Inputs!$B$4) -> 0.052043666 | O6: =IF(A6="",0,(J6<=Inputs!$B$11)+(L6<=Inputs!$B$11)+(N6<=Inputs!$B$11)) -> 3 | P6: =IF(A6="",0,(J6<=Inputs!$B$12)+(L6<=Inputs!$B$12)+(N6<=Inputs!$B$12)) -> 3 | Q6: Y | R6: Y | S6: =IF(A6="",0,(Inputs!$B$17+Inputs!$B$16*B6)/60) -> 1.3535534 | T6: =IF(A6="","Summer wind sea",IF(B6<Inputs!$B$28,"Below min comfortable wavemaker period. ","")&IF(OR(ABS(A6-Inputs!$C$38)<=Inputs!$B$32,ABS(A6-Inputs!$C$40)<=Inputs!$B$32),"Near symmetric flume cross-mode – check cross-flume gauges. ","")&IF(OR(ABS(A6-Inputs!$C$37)<=Inputs!$B$32,ABS(A6-Inputs!$C$39)<=Inputs!$B$32),"Near antisymmetric cross-mode – verify model centred. ","")&"Summer wind sea") -> Summer wind sea
A7: 6 | B7: =IF(A7="","",A7/SQRT(Inputs!$B$4)) -> 0.84852814 | C7: =IF(A7="","",Inputs!$B$25*A7^2/(2*PI())) -> 56.20716 | D7: =IF(A7="","",C7*TANH((2*PI()*Inputs!$B$8/C7)^0.75)^(2/3)) -> 56.207146 | E7: =IF(A7="","",2*PI()*Inputs!$B$8/D7) -> 15.314714 | F7: =IF(A7="","",IF(E7>=PI(),"Deep",IF(E7>=PI()/10,"Near-deep / intermediate","Shallow"))) -> Deep | G7: =IF(A7="","",C7*TANH((2*PI()*Inputs!$B$10/C7)^0.75)^(2/3)) -> 56.199247 | H7: =IF(A7="","",C7/Inputs!$B$27) -> 0.468393 | I7: =IF(A7="","",C7*Inputs!$B$13) -> 0.936786 | J7: =IF(A7="","",I7/Inputs!$B$4) -> 0.01873572 | K7: =IF(A7="","",C7*Inputs!$B$14) -> 1.873572 | L7: =IF(A7="","",K7/Inputs!$B$4) -> 0.03747144 | M7: =IF(A7="","",C7*Inputs!$B$15) -> 3.747144 | N7: =IF(A7="","",M7/Inputs!$B$4) -> 0.07494288 | O7: =IF(A7="",0,(J7<=Inputs!$B$11)+(L7<=Inputs!$B$11)+(N7<=Inputs!$B$11)) -> 3 | P7: =IF(A7="",0,(J7<=Inputs!$B$12)+(L7<=Inputs!$B$12)+(N7<=Inputs!$B$12)) -> 3 | Q7: Y | R7: N | S7: =IF(A7="",0,(Inputs!$B$17+Inputs!$B$16*B7)/60) -> 1.4242641 | T7: =IF(A7="","",IF(B7<Inputs!$B$28,"Below min comfortable wavemaker period. ","")&IF(OR(ABS(A7-Inputs!$C$38)<=Inputs!$B$32,ABS(A7-Inputs!$C$40)<=Inputs!$B$32),"Near symmetric flume cross-mode – check cross-flume gauges. ","")&IF(OR(ABS(A7-Inputs!$C$37)<=Inputs!$B$32,ABS(A7-Inputs!$C$39)<=Inputs!$B$32),"Near antisymmetric cross-mode – verify model centred. ","")&"")
A8: 7 | B8: =IF(A8="","",A8/SQRT(Inputs!$B$4)) -> 0.98994949 | C8: =IF(A8="","",Inputs!$B$25*A8^2/(2*PI())) -> 76.50419 | D8: =IF(A8="","",C8*TANH((2*PI()*Inputs!$B$8/C8)^0.75)^(2/3)) -> 76.503719 | E8: =IF(A8="","",2*PI()*Inputs!$B$8/D8) -> 11.251693 | F8: =IF(A8="","",IF(E8>=PI(),"Deep",IF(E8>=PI()/10,"Near-deep / intermediate","Shallow"))) -> Deep | G8: =IF(A8="","",C8*TANH((2*PI()*Inputs!$B$10/C8)^0.75)^(2/3)) -> 76.432916 | H8: =IF(A8="","",C8/Inputs!$B$27) -> 0.63753491 | I8: =IF(A8="","",C8*Inputs!$B$13) -> 1.2750698 | J8: =IF(A8="","",I8/Inputs!$B$4) -> 0.025501397 | K8: =IF(A8="","",C8*Inputs!$B$14) -> 2.5501397 | L8: =IF(A8="","",K8/Inputs!$B$4) -> 0.051002793 | M8: =IF(A8="","",C8*Inputs!$B$15) -> 5.1002793 | N8: =IF(A8="","",M8/Inputs!$B$4) -> 0.10200559 | O8: =IF(A8="",0,(J8<=Inputs!$B$11)+(L8<=Inputs!$B$11)+(N8<=Inputs!$B$11)) -> 3 | P8: =IF(A8="",0,(J8<=Inputs!$B$12)+(L8<=Inputs!$B$12)+(N8<=Inputs!$B$12)) -> 3 | Q8: Y | R8: N | S8: =IF(A8="",0,(Inputs!$B$17+Inputs!$B$16*B8)/60) -> 1.4949747 | T8: =IF(A8="","",IF(B8<Inputs!$B$28,"Below min comfortable wavemaker period. ","")&IF(OR(ABS(A8-Inputs!$C$38)<=Inputs!$B$32,ABS(A8-Inputs!$C$40)<=Inputs!$B$32),"Near symmetric flume cross-mode – check cross-flume gauges. ","")&IF(OR(ABS(A8-Inputs!$C$37)<=Inputs!$B$32,ABS(A8-Inputs!$C$39)<=Inputs!$B$32),"Near antisymmetric cross-mode – verify model centred. ","")&"")
A9: 8 | B9: =IF(A9="","",A9/SQRT(Inputs!$B$4)) -> 1.1313708 | C9: =IF(A9="","",Inputs!$B$25*A9^2/(2*PI())) -> 99.923839 | D9: =IF(A9="","",C9*TANH((2*PI()*Inputs!$B$8/C9)^0.75)^(2/3)) -> 99.918124 | E9: =IF(A9="","",2*PI()*Inputs!$B$8/D9) -> 8.6150175 | F9: =IF(A9="","",IF(E9>=PI(),"Deep",IF(E9>=PI()/10,"Near-deep / intermediate","Shallow"))) -> Deep | G9: =IF(A9="","",C9*TANH((2*PI()*Inputs!$B$10/C9)^0.75)^(2/3)) -> 99.576206 | H9: =IF(A9="","",C9/Inputs!$B$27) -> 0.83269866 | I9: =IF(A9="","",C9*Inputs!$B$13) -> 1.6653973 | J9: =IF(A9="","",I9/Inputs!$B$4) -> 0.033307946 | K9: =IF(A9="","",C9*Inputs!$B$14) -> 3.3307946 | L9: =IF(A9="","",K9/Inputs!$B$4) -> 0.066615893 | M9: =IF(A9="","",C9*Inputs!$B$15) -> 6.6615893 | N9: =IF(A9="","",M9/Inputs!$B$4) -> 0.13323179 | O9: =IF(A9="",0,(J9<=Inputs!$B$11)+(L9<=Inputs!$B$11)+(N9<=Inputs!$B$11)) -> 3 | P9: =IF(A9="",0,(J9<=Inputs!$B$12)+(L9<=Inputs!$B$12)+(N9<=Inputs!$B$12)) -> 3 | Q9: Y | R9: Y | S9: =IF(A9="",0,(Inputs!$B$17+Inputs!$B$16*B9)/60) -> 1.5656854 | T9: =IF(A9="","",IF(B9<Inputs!$B$28,"Below min comfortable wavemaker period. ","")&IF(OR(ABS(A9-Inputs!$C$38)<=Inputs!$B$32,ABS(A9-Inputs!$C$40)<=Inputs!$B$32),"Near symmetric flume cross-mode – check cross-flume gauges. ","")&IF(OR(ABS(A9-Inputs!$C$37)<=Inputs!$B$32,ABS(A9-Inputs!$C$39)<=Inputs!$B$32),"Near antisymmetric cross-mode – verify model centred. ","")&"") -> Near symmetric flume cross-mode – check cross-flume gauges.
A10: 8.5 | B10: =IF(A10="","",A10/SQRT(Inputs!$B$4)) -> 1.2020815 | C10: =IF(A10="","",Inputs!$B$25*A10^2/(2*PI())) -> 112.80465 | D10: =IF(A10="","",C10*TANH((2*PI()*Inputs!$B$8/C10)^0.75)^(2/3)) -> 112.78918 | E10: =IF(A10="","",2*PI()*Inputs!$B$8/D10) -> 7.6319055 | F10: =IF(A10="","",IF(E10>=PI(),"Deep",IF(E10>=PI()/10,"Near-deep / intermediate","Shallow"))) -> Deep | G10: =IF(A10="","",C10*TANH((2*PI()*Inputs!$B$10/C10)^0.75)^(2/3)) -> 112.14733 | H10: =IF(A10="","",C10/Inputs!$B$27) -> 0.94003872 | I10: =IF(A10="","",C10*Inputs!$B$13) -> 1.8800774 | J10: =IF(A10="","",I10/Inputs!$B$4) -> 0.037601549 | K10: =IF(A10="","",C10*Inputs!$B$14) -> 3.7601549 | L10: =IF(A10="","",K10/Inputs!$B$4) -> 0.075203098 | M10: =IF(A10="","",C10*Inputs!$B$15) -> 7.5203098 | N10: =IF(A10="","",M10/Inputs!$B$4) -> 0.1504062 | O10: =IF(A10="",0,(J10<=Inputs!$B$11)+(L10<=Inputs!$B$11)+(N10<=Inputs!$B$11)) -> 3 | P10: =IF(A10="",0,(J10<=Inputs!$B$12)+(L10<=Inputs!$B$12)+(N10<=Inputs!$B$12)) -> 3 | Q10: Y | R10: N | S10: =IF(A10="",0,(Inputs!$B$17+Inputs!$B$16*B10)/60) -> 1.6010408 | T10: =IF(A10="","Wavelength ≈ footprint band",IF(B10<Inputs!$B$28,"Below min comfortable wavemaker period. ","")&IF(OR(ABS(A10-Inputs!$C$38)<=Inputs!$B$32,ABS(A10-Inputs!$C$40)<=Inputs!$B$32),"Near symmetric flume cross-mode – check cross-flume gauges. ","")&IF(OR(ABS(A10-Inputs!$C$37)<=Inputs!$B$32,ABS(A10-Inputs!$C$39)<=Inputs!$B$32),"Near antisymmetric cross-mode – verify model centred. ","")&"Wavelength ≈ footprint band") -> Near antisymmetric cross-mode – verify model centred. Wavelength ≈ footprint band
A11: 9 | B11: =IF(A11="","",A11/SQRT(Inputs!$B$4)) -> 1.2727922 | C11: =IF(A11="","",Inputs!$B$25*A11^2/(2*PI())) -> 126.46611 | D11: =IF(A11="","",C11*TANH((2*PI()*Inputs!$B$8/C11)^0.75)^(2/3)) -> 126.42924 | E11: =IF(A11="","",2*PI()*Inputs!$B$8/D11) -> 6.8085228 | F11: =IF(A11="","",IF(E11>=PI(),"Deep",IF(E11>=PI()/10,"Near-deep / intermediate","Shallow"))) -> Deep | G11: =IF(A11="","",C11*TANH((2*PI()*Inputs!$B$10/C11)^0.75)^(2/3)) -> 125.3167 | H11: =IF(A11="","",C11/Inputs!$B$27) -> 1.0538842 | I11: =IF(A11="","",C11*Inputs!$B$13) -> 2.1077685 | J11: =IF(A11="","",I11/Inputs!$B$4) -> 0.04215537 | K11: =IF(A11="","",C11*Inputs!$B$14) -> 4.215537 | L11: =IF(A11="","",K11/Inputs!$B$4) -> 0.08431074 | M11: =IF(A11="","",C11*Inputs!$B$15) -> 8.431074 | N11: =IF(A11="","",M11/Inputs!$B$4) -> 0.16862148 | O11: =IF(A11="",0,(J11<=Inputs!$B$11)+(L11<=Inputs!$B$11)+(N11<=Inputs!$B$11)) -> 3 | P11: =IF(A11="",0,(J11<=Inputs!$B$12)+(L11<=Inputs!$B$12)+(N11<=Inputs!$B$12)) -> 3 | Q11: Y | R11: N | S11: =IF(A11="",0,(Inputs!$B$17+Inputs!$B$16*B11)/60) -> 1.6363961 | T11: =IF(A11="","Wavelength ≈ footprint band",IF(B11<Inputs!$B$28,"Below min comfortable wavemaker period. ","")&IF(OR(ABS(A11-Inputs!$C$38)<=Inputs!$B$32,ABS(A11-Inputs!$C$40)<=Inputs!$B$32),"Near symmetric flume cross-mode – check cross-flume gauges. ","")&IF(OR(ABS(A11-Inputs!$C$37)<=Inputs!$B$32,ABS(A11-Inputs!$C$39)<=Inputs!$B$32),"Near antisymmetric cross-mode – verify model centred. ","")&"Wavelength ≈ footprint band") -> Near antisymmetric cross-mode – verify model centred. Wavelength ≈ footprint band
A12: 9.5 | B12: =IF(A12="","",A12/SQRT(Inputs!$B$4)) -> 1.3435029 | C12: =IF(A12="","",Inputs!$B$25*A12^2/(2*PI())) -> 140.90823 | D12: =IF(A12="","",C12*TANH((2*PI()*Inputs!$B$8/C12)^0.75)^(2/3)) -> 140.82904 | E12: =IF(A12="","",2*PI()*Inputs!$B$8/D12) -> 6.11235 | F12: =IF(A12="","",IF(E12>=PI(),"Deep",IF(E12>=PI()/10,"Near-deep / intermediate","Shallow"))) -> Deep | G12: =IF(A12="","",C12*TANH((2*PI()*Inputs!$B$10/C12)^0.75)^(2/3)) -> 139.02407 | H12: =IF(A12="","",C12/Inputs!$B$27) -> 1.1742352 | I12: =IF(A12="","",C12*Inputs!$B$13) -> 2.3484704 | J12: =IF(A12="","",I12/Inputs!$B$4) -> 0.046969409 | K12: =IF(A12="","",C12*Inputs!$B$14) -> 4.6969409 | L12: =IF(A12="","",K12/Inputs!$B$4) -> 0.093938818 | M12: =IF(A12="","",C12*Inputs!$B$15) -> 9.3938818 | N12: =IF(A12="","",M12/Inputs!$B$4) -> 0.18787764 | O12: =IF(A12="",0,(J12<=Inputs!$B$11)+(L12<=Inputs!$B$11)+(N12<=Inputs!$B$11)) -> 3 | P12: =IF(A12="",0,(J12<=Inputs!$B$12)+(L12<=Inputs!$B$12)+(N12<=Inputs!$B$12)) -> 3 | Q12: Y | R12: N | S12: =IF(A12="",0,(Inputs!$B$17+Inputs!$B$16*B12)/60) -> 1.6717514 | T12: =IF(A12="","Wavelength ≈ footprint band",IF(B12<Inputs!$B$28,"Below min comfortable wavemaker period. ","")&IF(OR(ABS(A12-Inputs!$C$38)<=Inputs!$B$32,ABS(A12-Inputs!$C$40)<=Inputs!$B$32),"Near symmetric flume cross-mode – check cross-flume gauges. ","")&IF(OR(ABS(A12-Inputs!$C$37)<=Inputs!$B$32,ABS(A12-Inputs!$C$39)<=Inputs!$B$32),"Near antisymmetric cross-mode – verify model centred. ","")&"Wavelength ≈ footprint band") -> Wavelength ≈ footprint band
A13: 10 | B13: =IF(A13="","",A13/SQRT(Inputs!$B$4)) -> 1.4142136 | C13: =IF(A13="","",Inputs!$B$25*A13^2/(2*PI())) -> 156.131 | D13: =IF(A13="","",C13*TANH((2*PI()*Inputs!$B$8/C13)^0.75)^(2/3)) -> 155.97503 | E13: =IF(A13="","",2*PI()*Inputs!$B$8/D13) -> 5.518809 | F13: =IF(A13="","",IF(E13>=PI(),"Deep",IF(E13>=PI()/10,"Near-deep / intermediate","Shallow"))) -> Deep | G13: =IF(A13="","",C13*TANH((2*PI()*Inputs!$B$10/C13)^0.75)^(2/3)) -> 153.2048 | H13: =IF(A13="","",C13/Inputs!$B$27) -> 1.3010917 | I13: =IF(A13="","",C13*Inputs!$B$13) -> 2.6021833 | J13: =IF(A13="","",I13/Inputs!$B$4) -> 0.052043666 | K13: =IF(A13="","",C13*Inputs!$B$14) -> 5.2043666 | L13: =IF(A13="","",K13/Inputs!$B$4) -> 0.10408733 | M13: =IF(A13="","",C13*Inputs!$B$15) -> 10.408733 | N13: =IF(A13="","",M13/Inputs!$B$4) -> 0.20817467 | O13: =IF(A13="",0,(J13<=Inputs!$B$11)+(L13<=Inputs!$B$11)+(N13<=Inputs!$B$11)) -> 3 | P13: =IF(A13="",0,(J13<=Inputs!$B$12)+(L13<=Inputs!$B$12)+(N13<=Inputs!$B$12)) -> 3 | Q13: Y | R13: Y | S13: =IF(A13="",0,(Inputs!$B$17+Inputs!$B$16*B13)/60) -> 1.7071068 | T13: =IF(A13="","",IF(B13<Inputs!$B$28,"Below min comfortable wavemaker period. ","")&IF(OR(ABS(A13-Inputs!$C$38)<=Inputs!$B$32,ABS(A13-Inputs!$C$40)<=Inputs!$B$32),"Near symmetric flume cross-mode – check cross-flume gauges. ","")&IF(OR(ABS(A13-Inputs!$C$37)<=Inputs!$B$32,ABS(A13-Inputs!$C$39)<=Inputs!$B$32),"Near antisymmetric cross-mode – verify model centred. ","")&"")
A14: 11 | B14: =IF(A14="","",A14/SQRT(Inputs!$B$4)) -> 1.5556349 | C14: =IF(A14="","",Inputs!$B$25*A14^2/(2*PI())) -> 188.91851 | D14: =IF(A14="","",C14*TANH((2*PI()*Inputs!$B$8/C14)^0.75)^(2/3)) -> 188.42669 | E14: =IF(A14="","",2*PI()*Inputs!$B$8/D14) -> 4.5683358 | F14: =IF(A14="","",IF(E14>=PI(),"Deep",IF(E14>=PI()/10,"Near-deep / intermediate","Shallow"))) -> Deep | G14: =IF(A14="","",C14*TANH((2*PI()*Inputs!$B$10/C14)^0.75)^(2/3)) -> 182.72097 | H14: =IF(A14="","",C14/Inputs!$B$27) -> 1.5743209 | I14: =IF(A14="","",C14*Inputs!$B$13) -> 3.1486418 | J14: =IF(A14="","",I14/Inputs!$B$4) -> 0.062972836 | K14: =IF(A14="","",C14*Inputs!$B$14) -> 6.2972836 | L14: =IF(A14="","",K14/Inputs!$B$4) -> 0.12594567 | M14: =IF(A14="","",C14*Inputs!$B$15) -> 12.594567 | N14: =IF(A14="","",M14/Inputs!$B$4) -> 0.25189135 | O14: =IF(A14="",0,(J14<=Inputs!$B$11)+(L14<=Inputs!$B$11)+(N14<=Inputs!$B$11)) -> 3 | P14: =IF(A14="",0,(J14<=Inputs!$B$12)+(L14<=Inputs!$B$12)+(N14<=Inputs!$B$12)) -> 3 | Q14: Y | R14: N | S14: =IF(A14="",0,(Inputs!$B$17+Inputs!$B$16*B14)/60) -> 1.7778175 | T14: =IF(A14="","",IF(B14<Inputs!$B$28,"Below min comfortable wavemaker period. ","")&IF(OR(ABS(A14-Inputs!$C$38)<=Inputs!$B$32,ABS(A14-Inputs!$C$40)<=Inputs!$B$32),"Near symmetric flume cross-mode – check cross-flume gauges. ","")&IF(OR(ABS(A14-Inputs!$C$37)<=Inputs!$B$32,ABS(A14-Inputs!$C$39)<=Inputs!$B$32),"Near antisymmetric cross-mode – verify model centred. ","")&"") -> Near symmetric flume cross-mode – check cross-flume gauges.
A15: 12 | B15: =IF(A15="","",A15/SQRT(Inputs!$B$4)) -> 1.6970563 | C15: =IF(A15="","",Inputs!$B$25*A15^2/(2*PI())) -> 224.82864 | D15: =IF(A15="","",C15*TANH((2*PI()*Inputs!$B$8/C15)^0.75)^(2/3)) -> 223.57496 | E15: =IF(A15="","",2*PI()*Inputs!$B$8/D15) -> 3.8501467 | F15: =IF(A15="","",IF(E15>=PI(),"Deep",IF(E15>=PI()/10,"Near-deep / intermediate","Shallow"))) -> Deep | G15: =IF(A15="","",C15*TANH((2*PI()*Inputs!$B$10/C15)^0.75)^(2/3)) -> 213.35172 | H15: =IF(A15="","",C15/Inputs!$B$27) -> 1.873572 | I15: =IF(A15="","",C15*Inputs!$B$13) -> 3.747144 | J15: =IF(A15="","",I15/Inputs!$B$4) -> 0.07494288 | K15: =IF(A15="","",C15*Inputs!$B$14) -> 7.494288 | L15: =IF(A15="","",K15/Inputs!$B$4) -> 0.14988576 | M15: =IF(A15="","",C15*Inputs!$B$15) -> 14.988576 | N15: =IF(A15="","",M15/Inputs!$B$4) -> 0.29977152 | O15: =IF(A15="",0,(J15<=Inputs!$B$11)+(L15<=Inputs!$B$11)+(N15<=Inputs!$B$11)) -> 3 | P15: =IF(A15="",0,(J15<=Inputs!$B$12)+(L15<=Inputs!$B$12)+(N15<=Inputs!$B$12)) -> 3 | Q15: Y | R15: Y | S15: =IF(A15="",0,(Inputs!$B$17+Inputs!$B$16*B15)/60) -> 1.8485281 | T15: =IF(A15="","Winter mean peak period (~12 s)",IF(B15<Inputs!$B$28,"Below min comfortable wavemaker period. ","")&IF(OR(ABS(A15-Inputs!$C$38)<=Inputs!$B$32,ABS(A15-Inputs!$C$40)<=Inputs!$B$32),"Near symmetric flume cross-mode – check cross-flume gauges. ","")&IF(OR(ABS(A15-Inputs!$C$37)<=Inputs!$B$32,ABS(A15-Inputs!$C$39)<=Inputs!$B$32),"Near antisymmetric cross-mode – verify model centred. ","")&"Winter mean peak period (~12 s)") -> Winter mean peak period (~12 s)
A16: 13 | B16: =IF(A16="","",A16/SQRT(Inputs!$B$4)) -> 1.8384776 | C16: =IF(A16="","",Inputs!$B$25*A16^2/(2*PI())) -> 263.86139 | D16: =IF(A16="","",C16*TANH((2*PI()*Inputs!$B$8/C16)^0.75)^(2/3)) -> 261.13463 | E16: =IF(A16="","",2*PI()*Inputs!$B$8/D16) -> 3.2963701 | F16: =IF(A16="","",IF(E16>=PI(),"Deep",IF(E16>=PI()/10,"Near-deep / intermediate","Shallow"))) -> Deep | G16: =IF(A16="","",C16*TANH((2*PI()*Inputs!$B$10/C16)^0.75)^(2/3)) -> 244.64562 | H16: =IF(A16="","",C16/Inputs!$B$27) -> 2.1988449 | I16: =IF(A16="","",C16*Inputs!$B$13) -> 4.3976898 | J16: =IF(A16="","",I16/Inputs!$B$4) -> 0.087953796 | K16: =IF(A16="","",C16*Inputs!$B$14) -> 8.7953796 | L16: =IF(A16="","",K16/Inputs!$B$4) -> 0.17590759 | M16: =IF(A16="","",C16*Inputs!$B$15) -> 17.590759 | N16: =IF(A16="","",M16/Inputs!$B$4) -> 0.35181518 | O16: =IF(A16="",0,(J16<=Inputs!$B$11)+(L16<=Inputs!$B$11)+(N16<=Inputs!$B$11)) -> 3 | P16: =IF(A16="",0,(J16<=Inputs!$B$12)+(L16<=Inputs!$B$12)+(N16<=Inputs!$B$12)) -> 3 | Q16: Y | R16: N | S16: =IF(A16="",0,(Inputs!$B$17+Inputs!$B$16*B16)/60) -> 1.9192388 | T16: =IF(A16="","",IF(B16<Inputs!$B$28,"Below min comfortable wavemaker period. ","")&IF(OR(ABS(A16-Inputs!$C$38)<=Inputs!$B$32,ABS(A16-Inputs!$C$40)<=Inputs!$B$32),"Near symmetric flume cross-mode – check cross-flume gauges. ","")&IF(OR(ABS(A16-Inputs!$C$37)<=Inputs!$B$32,ABS(A16-Inputs!$C$39)<=Inputs!$B$32),"Near antisymmetric cross-mode – verify model centred. ","")&"")
A17: 14 | B17: =IF(A17="","",A17/SQRT(Inputs!$B$4)) -> 1.979899 | C17: =IF(A17="","",Inputs!$B$25*A17^2/(2*PI())) -> 306.01676 | D17: =IF(A17="","",C17*TANH((2*PI()*Inputs!$B$8/C17)^0.75)^(2/3)) -> 300.76445 | E17: =IF(A17="","",2*PI()*Inputs!$B$8/D17) -> 2.8620284 | F17: =IF(A17="","",IF(E17>=PI(),"Deep",IF(E17>=PI()/10,"Near-deep / intermediate","Shallow"))) -> Near-deep / intermediate | G17: =IF(A17="","",C17*TANH((2*PI()*Inputs!$B$10/C17)^0.75)^(2/3)) -> 276.24102 | H17: =IF(A17="","",C17/Inputs!$B$27) -> 2.5501397 | I17: =IF(A17="","",C17*Inputs!$B$13) -> 5.1002793 | J17: =IF(A17="","",I17/Inputs!$B$4) -> 0.10200559 | K17: =IF(A17="","",C17*Inputs!$B$14) -> 10.200559 | L17: =IF(A17="","",K17/Inputs!$B$4) -> 0.20401117 | M17: =IF(A17="","",C17*Inputs!$B$15) -> 20.401117 | N17: =IF(A17="","",M17/Inputs!$B$4) -> 0.40802234 | O17: =IF(A17="",0,(J17<=Inputs!$B$11)+(L17<=Inputs!$B$11)+(N17<=Inputs!$B$11)) -> 3 | P17: =IF(A17="",0,(J17<=Inputs!$B$12)+(L17<=Inputs!$B$12)+(N17<=Inputs!$B$12)) -> 3 | Q17: Y | R17: N | S17: =IF(A17="",0,(Inputs!$B$17+Inputs!$B$16*B17)/60) -> 1.9899495 | T17: =IF(A17="","",IF(B17<Inputs!$B$28,"Below min comfortable wavemaker period. ","")&IF(OR(ABS(A17-Inputs!$C$38)<=Inputs!$B$32,ABS(A17-Inputs!$C$40)<=Inputs!$B$32),"Near symmetric flume cross-mode – check cross-flume gauges. ","")&IF(OR(ABS(A17-Inputs!$C$37)<=Inputs!$B$32,ABS(A17-Inputs!$C$39)<=Inputs!$B$32),"Near antisymmetric cross-mode – verify model centred. ","")&"")
A18: 15 | B18: =IF(A18="","",A18/SQRT(Inputs!$B$4)) -> 2.1213203 | C18: =IF(A18="","",Inputs!$B$25*A18^2/(2*PI())) -> 351.29475 | D18: =IF(A18="","",C18*TANH((2*PI()*Inputs!$B$8/C18)^0.75)^(2/3)) -> 342.09462 | E18: =IF(A18="","",2*PI()*Inputs!$B$8/D18) -> 2.5162524 | F18: =IF(A18="","",IF(E18>=PI(),"Deep",IF(E18>=PI()/10,"Near-deep / intermediate","Shallow"))) -> Near-deep / intermediate | G18: =IF(A18="","",C18*TANH((2*PI()*Inputs!$B$10/C18)^0.75)^(2/3)) -> 307.87012 | H18: =IF(A18="","",C18/Inputs!$B$27) -> 2.9274562 | I18: =IF(A18="","",C18*Inputs!$B$13) -> 5.8549125 | J18: =IF(A18="","",I18/Inputs!$B$4) -> 0.11709825 | K18: =IF(A18="","",C18*Inputs!$B$14) -> 11.709825 | L18: =IF(A18="","",K18/Inputs!$B$4) -> 0.2341965 | M18: =IF(A18="","",C18*Inputs!$B$15) -> 23.41965 | N18: =IF(A18="","",M18/Inputs!$B$4) -> 0.468393 | O18: =IF(A18="",0,(J18<=Inputs!$B$11)+(L18<=Inputs!$B$11)+(N18<=Inputs!$B$11)) -> 3 | P18: =IF(A18="",0,(J18<=Inputs!$B$12)+(L18<=Inputs!$B$12)+(N18<=Inputs!$B$12)) -> 3 | Q18: Y | R18: Y | S18: =IF(A18="",0,(Inputs!$B$17+Inputs!$B$16*B18)/60) -> 2.0606602 | T18: =IF(A18="","Storm peak periods 12.5–20 s",IF(B18<Inputs!$B$28,"Below min comfortable wavemaker period. ","")&IF(OR(ABS(A18-Inputs!$C$38)<=Inputs!$B$32,ABS(A18-Inputs!$C$40)<=Inputs!$B$32),"Near symmetric flume cross-mode – check cross-flume gauges. ","")&IF(OR(ABS(A18-Inputs!$C$37)<=Inputs!$B$32,ABS(A18-Inputs!$C$39)<=Inputs!$B$32),"Near antisymmetric cross-mode – verify model centred. ","")&"Storm peak periods 12.5–20 s") -> Storm peak periods 12.5–20 s
A19: 16 | B19: =IF(A19="","",A19/SQRT(Inputs!$B$4)) -> 2.2627417 | C19: =IF(A19="","",Inputs!$B$25*A19^2/(2*PI())) -> 399.69536 | D19: =IF(A19="","",C19*TANH((2*PI()*Inputs!$B$8/C19)^0.75)^(2/3)) -> 384.75442 | E19: =IF(A19="","",2*PI()*Inputs!$B$8/D19) -> 2.2372618 | F19: =IF(A19="","",IF(E19>=PI(),"Deep",IF(E19>=PI()/10,"Near-deep / intermediate","Shallow"))) -> Near-deep / intermediate | G19: =IF(A19="","",C19*TANH((2*PI()*Inputs!$B$10/C19)^0.75)^(2/3)) -> 339.34888 | H19: =IF(A19="","",C19/Inputs!$B$27) -> 3.3307946 | I19: =IF(A19="","",C19*Inputs!$B$13) -> 6.6615893 | J19: =IF(A19="","",I19/Inputs!$B$4) -> 0.13323179 | K19: =IF(A19="","",C19*Inputs!$B$14) -> 13.323179 | L19: =IF(A19="","",K19/Inputs!$B$4) -> 0.26646357 | M19: =IF(A19="","",C19*Inputs!$B$15) -> 26.646357 | N19: =IF(A19="","",M19/Inputs!$B$4) -> 0.53292714 | O19: =IF(A19="",0,(J19<=Inputs!$B$11)+(L19<=Inputs!$B$11)+(N19<=Inputs!$B$11)) -> 3 | P19: =IF(A19="",0,(J19<=Inputs!$B$12)+(L19<=Inputs!$B$12)+(N19<=Inputs!$B$12)) -> 3 | Q19: Y | R19: N | S19: =IF(A19="",0,(Inputs!$B$17+Inputs!$B$16*B19)/60) -> 2.1313708 | T19: =IF(A19="","",IF(B19<Inputs!$B$28,"Below min comfortable wavemaker period. ","")&IF(OR(ABS(A19-Inputs!$C$38)<=Inputs!$B$32,ABS(A19-Inputs!$C$40)<=Inputs!$B$32),"Near symmetric flume cross-mode – check cross-flume gauges. ","")&IF(OR(ABS(A19-Inputs!$C$37)<=Inputs!$B$32,ABS(A19-Inputs!$C$39)<=Inputs!$B$32),"Near antisymmetric cross-mode – verify model centred. ","")&"") -> Near antisymmetric cross-mode – verify model centred.
A20: 17 | B20: =IF(A20="","",A20/SQRT(Inputs!$B$4)) -> 2.4041631 | C20: =IF(A20="","",Inputs!$B$25*A20^2/(2*PI())) -> 451.21859 | D20: =IF(A20="","",C20*TANH((2*PI()*Inputs!$B$8/C20)^0.75)^(2/3)) -> 428.39487 | E20: =IF(A20="","",2*PI()*Inputs!$B$8/D20) -> 2.0093527 | F20: =IF(A20="","",IF(E20>=PI(),"Deep",IF(E20>=PI()/10,"Near-deep / intermediate","Shallow"))) -> Near-deep / intermediate | G20: =IF(A20="","",C20*TANH((2*PI()*Inputs!$B$10/C20)^0.75)^(2/3)) -> 370.56078 | H20: =IF(A20="","",C20/Inputs!$B$27) -> 3.7601549 | I20: =IF(A20="","",C20*Inputs!$B$13) -> 7.5203098 | J20: =IF(A20="","",I20/Inputs!$B$4) -> 0.1504062 | K20: =IF(A20="","",C20*Inputs!$B$14) -> 15.04062 | L20: =IF(A20="","",K20/Inputs!$B$4) -> 0.30081239 | M20: =IF(A20="","",C20*Inputs!$B$15) -> 30.081239 | N20: =IF(A20="","",M20/Inputs!$B$4) -> 0.60162478 | O20: =IF(A20="",0,(J20<=Inputs!$B$11)+(L20<=Inputs!$B$11)+(N20<=Inputs!$B$11)) -> 3 | P20: =IF(A20="",0,(J20<=Inputs!$B$12)+(L20<=Inputs!$B$12)+(N20<=Inputs!$B$12)) -> 3 | Q20: Y | R20: N | S20: =IF(A20="",0,(Inputs!$B$17+Inputs!$B$16*B20)/60) -> 2.2020815 | T20: =IF(A20="","",IF(B20<Inputs!$B$28,"Below min comfortable wavemaker period. ","")&IF(OR(ABS(A20-Inputs!$C$38)<=Inputs!$B$32,ABS(A20-Inputs!$C$40)<=Inputs!$B$32),"Near symmetric flume cross-mode – check cross-flume gauges. ","")&IF(OR(ABS(A20-Inputs!$C$37)<=Inputs!$B$32,ABS(A20-Inputs!$C$39)<=Inputs!$B$32),"Near antisymmetric cross-mode – verify model centred. ","")&"")
A21: 18 | B21: =IF(A21="","",A21/SQRT(Inputs!$B$4)) -> 2.5455844 | C21: =IF(A21="","",Inputs!$B$25*A21^2/(2*PI())) -> 505.86444 | D21: =IF(A21="","",C21*TANH((2*PI()*Inputs!$B$8/C21)^0.75)^(2/3)) -> 472.70409 | E21: =IF(A21="","",2*PI()*Inputs!$B$8/D21) -> 1.8210048 | F21: =IF(A21="","",IF(E21>=PI(),"Deep",IF(E21>=PI()/10,"Near-deep / intermediate","Shallow"))) -> Near-deep / intermediate | G21: =IF(A21="","",C21*TANH((2*PI()*Inputs!$B$10/C21)^0.75)^(2/3)) -> 401.43993 | H21: =IF(A21="","",C21/Inputs!$B$27) -> 4.215537 | I21: =IF(A21="","",C21*Inputs!$B$13) -> 8.431074 | J21: =IF(A21="","",I21/Inputs!$B$4) -> 0.16862148 | K21: =IF(A21="","",C21*Inputs!$B$14) -> 16.862148 | L21: =IF(A21="","",K21/Inputs!$B$4) -> 0.33724296 | M21: =IF(A21="","",C21*Inputs!$B$15) -> 33.724296 | N21: =IF(A21="","",M21/Inputs!$B$4) -> 0.67448592 | O21: =IF(A21="",0,(J21<=Inputs!$B$11)+(L21<=Inputs!$B$11)+(N21<=Inputs!$B$11)) -> 3 | P21: =IF(A21="",0,(J21<=Inputs!$B$12)+(L21<=Inputs!$B$12)+(N21<=Inputs!$B$12)) -> 3 | Q21: Y | R21: N | S21: =IF(A21="",0,(Inputs!$B$17+Inputs!$B$16*B21)/60) -> 2.2727922 | T21: =IF(A21="","",IF(B21<Inputs!$B$28,"Below min comfortable wavemaker period. ","")&IF(OR(ABS(A21-Inputs!$C$38)<=Inputs!$B$32,ABS(A21-Inputs!$C$40)<=Inputs!$B$32),"Near symmetric flume cross-mode – check cross-flume gauges. ","")&IF(OR(ABS(A21-Inputs!$C$37)<=Inputs!$B$32,ABS(A21-Inputs!$C$39)<=Inputs!$B$32),"Near antisymmetric cross-mode – verify model centred. ","")&"")
A22: 19 | B22: =IF(A22="","",A22/SQRT(Inputs!$B$4)) -> 2.6870058 | C22: =IF(A22="","",Inputs!$B$25*A22^2/(2*PI())) -> 563.63291 | D22: =IF(A22="","",C22*TANH((2*PI()*Inputs!$B$8/C22)^0.75)^(2/3)) -> 517.41561 | E22: =IF(A22="","",2*PI()*Inputs!$B$8/D22) -> 1.663646 | F22: =IF(A22="","",IF(E22>=PI(),"Deep",IF(E22>=PI()/10,"Near-deep / intermediate","Shallow"))) -> Near-deep / intermediate | G22: =IF(A22="","",C22*TANH((2*PI()*Inputs!$B$10/C22)^0.75)^(2/3)) -> 431.95631 | H22: =IF(A22="","",C22/Inputs!$B$27) -> 4.6969409 | I22: =IF(A22="","",C22*Inputs!$B$13) -> 9.3938818 | J22: =IF(A22="","",I22/Inputs!$B$4) -> 0.18787764 | K22: =IF(A22="","",C22*Inputs!$B$14) -> 18.787764 | L22: =IF(A22="","",K22/Inputs!$B$4) -> 0.37575527 | M22: =IF(A22="","",C22*Inputs!$B$15) -> 37.575527 | N22: =IF(A22="","",M22/Inputs!$B$4) -> 0.75151054 | O22: =IF(A22="",0,(J22<=Inputs!$B$11)+(L22<=Inputs!$B$11)+(N22<=Inputs!$B$11)) -> 3 | P22: =IF(A22="",0,(J22<=Inputs!$B$12)+(L22<=Inputs!$B$12)+(N22<=Inputs!$B$12)) -> 3 | Q22: Y | R22: N | S22: =IF(A22="",0,(Inputs!$B$17+Inputs!$B$16*B22)/60) -> 2.3435029 | T22: =IF(A22="","",IF(B22<Inputs!$B$28,"Below min comfortable wavemaker period. ","")&IF(OR(ABS(A22-Inputs!$C$38)<=Inputs!$B$32,ABS(A22-Inputs!$C$40)<=Inputs!$B$32),"Near symmetric flume cross-mode – check cross-flume gauges. ","")&IF(OR(ABS(A22-Inputs!$C$37)<=Inputs!$B$32,ABS(A22-Inputs!$C$39)<=Inputs!$B$32),"Near antisymmetric cross-mode – verify model centred. ","")&"")
A23: 20 | B23: =IF(A23="","",A23/SQRT(Inputs!$B$4)) -> 2.8284271 | C23: =IF(A23="","",Inputs!$B$25*A23^2/(2*PI())) -> 624.524 | D23: =IF(A23="","",C23*TANH((2*PI()*Inputs!$B$8/C23)^0.75)^(2/3)) -> 562.31061 | E23: =IF(A23="","",2*PI()*Inputs!$B$8/D23) -> 1.5308201 | F23: =IF(A23="","",IF(E23>=PI(),"Deep",IF(E23>=PI()/10,"Near-deep / intermediate","Shallow"))) -> Near-deep / intermediate | G23: =IF(A23="","",C23*TANH((2*PI()*Inputs!$B$10/C23)^0.75)^(2/3)) -> 462.104 | H23: =IF(A23="","",C23/Inputs!$B$27) -> 5.2043666 | I23: =IF(A23="","",C23*Inputs!$B$13) -> 10.408733 | J23: =IF(A23="","",I23/Inputs!$B$4) -> 0.20817467 | K23: =IF(A23="","",C23*Inputs!$B$14) -> 20.817467 | L23: =IF(A23="","",K23/Inputs!$B$4) -> 0.41634933 | M23: =IF(A23="","",C23*Inputs!$B$15) -> 41.634933 | N23: =IF(A23="","",M23/Inputs!$B$4) -> 0.83269866 | O23: =IF(A23="",0,(J23<=Inputs!$B$11)+(L23<=Inputs!$B$11)+(N23<=Inputs!$B$11)) -> 3 | P23: =IF(A23="",0,(J23<=Inputs!$B$12)+(L23<=Inputs!$B$12)+(N23<=Inputs!$B$12)) -> 2 | Q23: Y | R23: Y | S23: =IF(A23="",0,(Inputs!$B$17+Inputs!$B$16*B23)/60) -> 2.4142136 | T23: =IF(A23="","Upper bound (changed from 18 s)",IF(B23<Inputs!$B$28,"Below min comfortable wavemaker period. ","")&IF(OR(ABS(A23-Inputs!$C$38)<=Inputs!$B$32,ABS(A23-Inputs!$C$40)<=Inputs!$B$32),"Near symmetric flume cross-mode – check cross-flume gauges. ","")&IF(OR(ABS(A23-Inputs!$C$37)<=Inputs!$B$32,ABS(A23-Inputs!$C$39)<=Inputs!$B$32),"Near antisymmetric cross-mode – verify model centred. ","")&"Upper bound (changed from 18 s)") -> Upper bound (changed from 18 s)
A24: 17.9 | B24: =IF(A24="","",A24/SQRT(Inputs!$B$4)) -> 2.5314423 | C24: =IF(A24="","",Inputs!$B$25*A24^2/(2*PI())) -> 500.25933 | D24: =IF(A24="","",C24*TANH((2*PI()*Inputs!$B$8/C24)^0.75)^(2/3)) -> 468.25104 | E24: =IF(A24="","",2*PI()*Inputs!$B$8/D24) -> 1.8383224 | F24: =IF(A24="","",IF(E24>=PI(),"Deep",IF(E24>=PI()/10,"Near-deep / intermediate","Shallow"))) -> Near-deep / intermediate | G24: =IF(A24="","",C24*TANH((2*PI()*Inputs!$B$10/C24)^0.75)^(2/3)) -> 398.36806 | H24: =IF(A24="","",C24/Inputs!$B$27) -> 4.1688278 | I24: =IF(A24="","",C24*Inputs!$B$13) -> 8.3376556 | J24: =IF(A24="","",I24/Inputs!$B$4) -> 0.16675311 | K24: =IF(A24="","",C24*Inputs!$B$14) -> 16.675311 | L24: =IF(A24="","",K24/Inputs!$B$4) -> 0.33350622 | M24: =IF(A24="","",C24*Inputs!$B$15) -> 33.350622 | N24: =IF(A24="","",M24/Inputs!$B$4) -> 0.66701245 | O24: =IF(A24="",0,(J24<=Inputs!$B$11)+(L24<=Inputs!$B$11)+(N24<=Inputs!$B$11)) -> 3 | P24: =IF(A24="",0,(J24<=Inputs!$B$12)+(L24<=Inputs!$B$12)+(N24<=Inputs!$B$12)) -> 3 | Q24: N | R24: N | S24: =IF(A24="",0,(Inputs!$B$17+Inputs!$B$16*B24)/60) -> 2.2657211 | T24: =IF(A24="",_xlfn._LONGTEXT("FloatSim pre-test: heave natural period, moored: buoy 17.7, cluster 18.0, platform 18.1 s FS. Broad peak (zeta ~11 %): the 1 s grid resolves it. The heave RAO peaks later in waves (~18.5-19 s FS). Replace with the measured decay. See FloatSim_Predictions.",")"),IF(B24<Inputs!$B$28,"Below min comfortable wavemaker period. ","")&IF(OR(ABS(A24-Inputs!$C$38)<=Inputs!$B$32,ABS(A24-Inputs!$C$40)<=Inputs!$B$32),"Near symmetric flume cross-mode – check cross-flume gauges. ","")&IF(OR(ABS(A24-Inputs!$C$37)<=Inputs!$B$32,ABS(A24-Inputs!$C$39)<=Inputs!$B$32),"Near antisymmetric cross-mode – verify model centred. ","")&_xlfn._LONGTEXT("FloatSim pre-test: heave natural period, moored: buoy 17.7, cluster 18.0, platform 18.1 s FS. Broad peak (zeta ~11 %): the 1 s grid resolves it. The heave RAO peaks later in waves (~18.5-19 s FS). Replace with the measured decay. See FloatSim_Predictions.",")")) -> FloatSim pre-test: heave natural period, moored: buoy 17.7, cluster 18.0, platform 18.1 s FS. Broad peak (zeta ~11 %): the 1 s grid resolves it. The heave RAO peaks later in waves (~18.5-19 s FS). Replace with the measured decay. See FloatSim_Predictions.)
A25: 19.6 | B25: =IF(A25="","",A25/SQRT(Inputs!$B$4)) -> 2.7718586 | C25: =IF(A25="","",Inputs!$B$25*A25^2/(2*PI())) -> 599.79285 | D25: =IF(A25="","",C25*TANH((2*PI()*Inputs!$B$8/C25)^0.75)^(2/3)) -> 544.34265 | E25: =IF(A25="","",2*PI()*Inputs!$B$8/D25) -> 1.5813502 | F25: =IF(A25="","",IF(E25>=PI(),"Deep",IF(E25>=PI()/10,"Near-deep / intermediate","Shallow"))) -> Near-deep / intermediate | G25: =IF(A25="","",C25*TANH((2*PI()*Inputs!$B$10/C25)^0.75)^(2/3)) -> 450.08883 | H25: =IF(A25="","",C25/Inputs!$B$27) -> 4.9982737 | I25: =IF(A25="","",C25*Inputs!$B$13) -> 9.9965474 | J25: =IF(A25="","",I25/Inputs!$B$4) -> 0.19993095 | K25: =IF(A25="","",C25*Inputs!$B$14) -> 19.993095 | L25: =IF(A25="","",K25/Inputs!$B$4) -> 0.3998619 | M25: =IF(A25="","",C25*Inputs!$B$15) -> 39.98619 | N25: =IF(A25="","",M25/Inputs!$B$4) -> 0.7997238 | O25: =IF(A25="",0,(J25<=Inputs!$B$11)+(L25<=Inputs!$B$11)+(N25<=Inputs!$B$11)) -> 3 | P25: =IF(A25="",0,(J25<=Inputs!$B$12)+(L25<=Inputs!$B$12)+(N25<=Inputs!$B$12)) -> 3 | Q25: N | R25: N | S25: =IF(A25="",0,(Inputs!$B$17+Inputs!$B$16*B25)/60) -> 2.3859293 | T25: =IF(A25="","FloatSim pre-test: tilt/pitch natural period, moored (operational cords): buoy 18.8, cluster 19.6, platform 20.1 s FS. Sharp peak (zeta ~3-4 %): needs the fine-step band per configuration (FloatSim_Predictions). Replace with the measured decay.",IF(B25<Inputs!$B$28,"Below min comfortable wavemaker period. ","")&IF(OR(ABS(A25-Inputs!$C$38)<=Inputs!$B$32,ABS(A25-Inputs!$C$40)<=Inputs!$B$32),"Near symmetric flume cross-mode – check cross-flume gauges. ","")&IF(OR(ABS(A25-Inputs!$C$37)<=Inputs!$B$32,ABS(A25-Inputs!$C$39)<=Inputs!$B$32),"Near antisymmetric cross-mode – verify model centred. ","")&"FloatSim pre-test: tilt/pitch natural period, moored (operational cords): buoy 18.8, cluster 19.6, platform 20.1 s FS. Sharp peak (zeta ~3-4 %): needs the fine-step band per configuration (FloatSim_Predictions). Replace with the measured decay.") -> FloatSim pre-test: tilt/pitch natural period, moored (operational cords): buoy 18.8, cluster 19.6, platform 20.1 s FS. Sharp peak (zeta ~3-4 %): needs the fine-step band per configuration (FloatSim_Predictions). Replace with the measured decay.
A26: 20.6 | B26: =IF(A26="","",A26/SQRT(Inputs!$B$4)) -> 2.9132799 | C26: =IF(A26="","",Inputs!$B$25*A26^2/(2*PI())) -> 662.55751 | D26: =IF(A26="","",C26*TANH((2*PI()*Inputs!$B$8/C26)^0.75)^(2/3)) -> 589.26189 | E26: =IF(A26="","",2*PI()*Inputs!$B$8/D26) -> 1.4608044 | F26: =IF(A26="","",IF(E26>=PI(),"Deep",IF(E26>=PI()/10,"Near-deep / intermediate","Shallow"))) -> Near-deep / intermediate | G26: =IF(A26="","",C26*TANH((2*PI()*Inputs!$B$10/C26)^0.75)^(2/3)) -> 480.01911 | H26: =IF(A26="","",C26/Inputs!$B$27) -> 5.5213126 | I26: =IF(A26="","",C26*Inputs!$B$13) -> 11.042625 | J26: =IF(A26="","",I26/Inputs!$B$4) -> 0.2208525 | K26: =IF(A26="","",C26*Inputs!$B$14) -> 22.08525 | L26: =IF(A26="","",K26/Inputs!$B$4) -> 0.44170501 | M26: =IF(A26="","",C26*Inputs!$B$15) -> 44.170501 | N26: =IF(A26="","",M26/Inputs!$B$4) -> 0.88341001 | O26: =IF(A26="",0,(J26<=Inputs!$B$11)+(L26<=Inputs!$B$11)+(N26<=Inputs!$B$11)) -> 3 | P26: =IF(A26="",0,(J26<=Inputs!$B$12)+(L26<=Inputs!$B$12)+(N26<=Inputs!$B$12)) -> 2 | Q26: N | R26: N | S26: =IF(A26="",0,(Inputs!$B$17+Inputs!$B$16*B26)/60) -> 2.45664 | T26: =IF(A26="","FloatSim pre-test: platform tilt 20.1 s FS + 0.5 s, the resonance's upper flank, beyond the 20 s bound. Extend the sweep to ~22 s FS (FloatSim_Predictions).",IF(B26<Inputs!$B$28,"Below min comfortable wavemaker period. ","")&IF(OR(ABS(A26-Inputs!$C$38)<=Inputs!$B$32,ABS(A26-Inputs!$C$40)<=Inputs!$B$32),"Near symmetric flume cross-mode – check cross-flume gauges. ","")&IF(OR(ABS(A26-Inputs!$C$37)<=Inputs!$B$32,ABS(A26-Inputs!$C$39)<=Inputs!$B$32),"Near antisymmetric cross-mode – verify model centred. ","")&"FloatSim pre-test: platform tilt 20.1 s FS + 0.5 s, the resonance's upper flank, beyond the 20 s bound. Extend the sweep to ~22 s FS (FloatSim_Predictions).") -> FloatSim pre-test: platform tilt 20.1 s FS + 0.5 s, the resonance's upper flank, beyond the 20 s bound. Extend the sweep to ~22 s FS (FloatSim_Predictions).
A28: Wavelengths use Fenton's explicit dispersion approximation (±~1%). 'Levels feasible' counts steepness levels within the facility wave-height limit on Inputs. Depth regime: Deep if kd ≥ π.

Sheet Irregular_Seas
A1: Irregular Sea States (JONSWAP) – Site: ~200 mi west of Seattle
A2: Based on NDBC 46005 (West Washington, deep water) statistics. Refine with a site hindcast (e.g., WW3/WIS) Hs–Tp scatter and environmental contour.
A4: ID | B4: Category | C4: Hs FS (m) | D4: Tp FS (s) | E4: γ (peak) | F4: Spreading | G4: Seeds | H4: Full set (Y/N) | I4: Reduced set (Y/N) | J4: Hs model (m) | K4: Tp model (s) | L4: Est. Hmax model (m) | M4: OK in LWF (1/0) | N4: OK in DWB (1/0) | O4: Hs / Lp (deep) | P4: Run time (min, model) | Q4: Basis / purpose
A5: O1 | B5: Summer calm | C5: 1.5 | D5: 8 | E5: 3.3 | F5: Long-crested | G5: 1 | H5: Y | I5: N | J5: =C5/Inputs!$B$4 -> 0.03 | K5: =D5/SQRT(Inputs!$B$4) -> 1.1313708 | L5: =1.86*J5 -> 0.0558 | M5: =IF(AND(L5<=Inputs!$B$11,K5>=Inputs!$B$28),1,0) -> 1 | N5: =IF(AND(L5<=Inputs!$B$12,K5>=Inputs!$B$28),1,0) -> 1 | O5: =C5/(Inputs!$B$25*D5^2/(2*PI())) -> 0.015011433 | P5: =Inputs!$B$20*60/SQRT(Inputs!$B$4)+1 -> 26.455844 | Q5: Summer monthly means at 46005 ~1.5–2 m – access/maintenance window
A6: O2 | B6: Summer typical | C6: 2 | D6: 10 | E6: 3.3 | F6: Long-crested | G6: 1 | H6: Y | I6: Y | J6: =C6/Inputs!$B$4 -> 0.04 | K6: =D6/SQRT(Inputs!$B$4) -> 1.4142136 | L6: =1.86*J6 -> 0.0744 | M6: =IF(AND(L6<=Inputs!$B$11,K6>=Inputs!$B$28),1,0) -> 1 | N6: =IF(AND(L6<=Inputs!$B$12,K6>=Inputs!$B$28),1,0) -> 1 | O6: =C6/(Inputs!$B$25*D6^2/(2*PI())) -> 0.012809756 | P6: =Inputs!$B$20*60/SQRT(Inputs!$B$4)+1 -> 26.455844 | Q6: Typical summer operations
A7: O3 | B7: Annual mean | C7: 2.8 | D7: 11 | E7: 3.3 | F7: Long-crested | G7: 1 | H7: Y | I7: N | J7: =C7/Inputs!$B$4 -> 0.056 | K7: =D7/SQRT(Inputs!$B$4) -> 1.5556349 | L7: =1.86*J7 -> 0.10416 | M7: =IF(AND(L7<=Inputs!$B$11,K7>=Inputs!$B$28),1,0) -> 1 | N7: =IF(AND(L7<=Inputs!$B$12,K7>=Inputs!$B$28),1,0) -> 1 | O7: =C7/(Inputs!$B$25*D7^2/(2*PI())) -> 0.014821205 | P7: =Inputs!$B$20*60/SQRT(Inputs!$B$4)+1 -> 26.455844 | Q7: Approximate annual mean Hs offshore WA
A8: E1 | B8: Winter mean / energy design | C8: 3.7 | D8: 12.5 | E8: 3.3 | F8: Long-crested | G8: 1 | H8: Y | I8: Y | J8: =C8/Inputs!$B$4 -> 0.074 | K8: =D8/SQRT(Inputs!$B$4) -> 1.767767 | L8: =1.86*J8 -> 0.13764 | M8: =IF(AND(L8<=Inputs!$B$11,K8>=Inputs!$B$28),1,0) -> 1 | N8: =IF(AND(L8<=Inputs!$B$12,K8>=Inputs!$B$28),1,0) -> 1 | O8: =C8/(Inputs!$B$25*D8^2/(2*PI())) -> 0.015166751 | P8: =Inputs!$B$20*60/SQRT(Inputs!$B$4)+1 -> 26.455844 | Q8: Winter monthly mean Hs 3.6–3.8 m, Tp ~12 s (Allen & Komar / DLCD 2000) – WEC design sea
A9: SW1 | B9: Long swell | C9: 2.5 | D9: 16 | E9: 5 | F9: Long-crested | G9: 1 | H9: Y | I9: N | J9: =C9/Inputs!$B$4 -> 0.05 | K9: =D9/SQRT(Inputs!$B$4) -> 2.2627417 | L9: =1.86*J9 -> 0.093 | M9: =IF(AND(L9<=Inputs!$B$11,K9>=Inputs!$B$28),1,0) -> 1 | N9: =IF(AND(L9<=Inputs!$B$12,K9>=Inputs!$B$28),1,0) -> 1 | O9: =C9/(Inputs!$B$25*D9^2/(2*PI())) -> 0.0062547637 | P9: =Inputs!$B$20*60/SQRT(Inputs!$B$4)+1 -> 26.455844 | Q9: Distant-storm swell; near long spar natural periods?
A10: SW2 | B10: Very long swell | C10: 3 | D10: 20 | E10: 5 | F10: Long-crested | G10: 1 | H10: Y | I10: N | J10: =C10/Inputs!$B$4 -> 0.06 | K10: =D10/SQRT(Inputs!$B$4) -> 2.8284271 | L10: =1.86*J10 -> 0.1116 | M10: =IF(AND(L10<=Inputs!$B$11,K10>=Inputs!$B$28),1,0) -> 1 | N10: =IF(AND(L10<=Inputs!$B$12,K10>=Inputs!$B$28),1,0) -> 1 | O10: =C10/(Inputs!$B$25*D10^2/(2*PI())) -> 0.0048036585 | P10: =Inputs!$B$20*60/SQRT(Inputs!$B$4)+1 -> 26.455844 | Q10: Upper period bound of matrix
A11: D1 | B11: Winter storm (ops limit) | C11: 6 | D11: 13 | E11: 3.3 | F11: Long-crested | G11: 2 | H11: Y | I11: N | J11: =C11/Inputs!$B$4 -> 0.12 | K11: =D11/SQRT(Inputs!$B$4) -> 1.8384776 | L11: =1.86*J11 -> 0.2232 | M11: =IF(AND(L11<=Inputs!$B$11,K11>=Inputs!$B$28),1,0) -> 1 | N11: =IF(AND(L11<=Inputs!$B$12,K11>=Inputs!$B$28),1,0) -> 1 | O11: =C11/(Inputs!$B$25*D11^2/(2*PI())) -> 0.022739212 | P11: =Inputs!$B$20*60/SQRT(Inputs!$B$4)+1 -> 26.455844 | Q11: Frequent winter storm – likely operational limit / transfer ops
A12: X1 | B12: ~Annual max storm | C12: 10 | D12: 15 | E12: 2 | F12: Long-crested | G12: 2 | H12: Y | I12: N | J12: =C12/Inputs!$B$4 -> 0.2 | K12: =D12/SQRT(Inputs!$B$4) -> 2.1213203 | L12: =1.86*J12 -> 0.372 | M12: =IF(AND(L12<=Inputs!$B$11,K12>=Inputs!$B$28),1,0) -> 1 | N12: =IF(AND(L12<=Inputs!$B$12,K12>=Inputs!$B$28),1,0) -> 1 | O12: =C12/(Inputs!$B$25*D12^2/(2*PI())) -> 0.028466124 | P12: =Inputs!$B$20*60/SQRT(Inputs!$B$4)+1 -> 26.455844 | Q12: Typical yearly maximum at 46005 (≈9–11 m) – ASSUMED, verify
A13: X10 | B13: 10-yr extreme | C13: 12.4 | D13: 16 | E13: 2 | F13: Long-crested | G13: 2 | H13: Y | I13: N | J13: =C13/Inputs!$B$4 -> 0.248 | K13: =D13/SQRT(Inputs!$B$4) -> 2.2627417 | L13: =1.86*J13 -> 0.46128 | M13: =IF(AND(L13<=Inputs!$B$11,K13>=Inputs!$B$28),1,0) -> 1 | N13: =IF(AND(L13<=Inputs!$B$12,K13>=Inputs!$B$28),1,0) -> 1 | O13: =C13/(Inputs!$B$25*D13^2/(2*PI())) -> 0.031023628 | P13: =Inputs!$B$20*60/SQRT(Inputs!$B$4)+1 -> 26.455844 | Q13: 46005 10-yr Hs 12.4 m (DLCD 2000, Table 1); Tp assumed
A14: X50 | B14: 50-yr extreme | C14: 14.3 | D14: 17 | E14: 2 | F14: Long-crested | G14: 3 | H14: Y | I14: Y | J14: =C14/Inputs!$B$4 -> 0.286 | K14: =D14/SQRT(Inputs!$B$4) -> 2.4041631 | L14: =1.86*J14 -> 0.53196 | M14: =IF(AND(L14<=Inputs!$B$11,K14>=Inputs!$B$28),1,0) -> 1 | N14: =IF(AND(L14<=Inputs!$B$12,K14>=Inputs!$B$28),1,0) -> 1 | O14: =C14/(Inputs!$B$25*D14^2/(2*PI())) -> 0.031691957 | P14: =Inputs!$B$20*60/SQRT(Inputs!$B$4)+1 -> 26.455844 | Q14: 46005 50-yr Hs 14.3 m (DLCD 2000); Tp assumed
A15: X100 | B15: 100-yr extreme | C15: 15 | D15: 17 | E15: 2 | F15: Long-crested | G15: 3 | H15: Y | I15: N | J15: =C15/Inputs!$B$4 -> 0.3 | K15: =D15/SQRT(Inputs!$B$4) -> 2.4041631 | L15: =1.86*J15 -> 0.558 | M15: =IF(AND(L15<=Inputs!$B$11,K15>=Inputs!$B$28),1,0) -> 1 | N15: =IF(AND(L15<=Inputs!$B$12,K15>=Inputs!$B$28),1,0) -> 1 | O15: =C15/(Inputs!$B$25*D15^2/(2*PI())) -> 0.033243311 | P15: =Inputs!$B$20*60/SQRT(Inputs!$B$4)+1 -> 26.455844 | Q15: 46005 100-yr Hs 15.0 m (DLCD 2000); Tp assumed (storms 12.5–20 s)
A16: X100L | B16: 100-yr, long Tp | C16: 15 | D16: 19 | E16: 2 | F16: Long-crested | G16: 2 | H16: Y | I16: N | J16: =C16/Inputs!$B$4 -> 0.3 | K16: =D16/SQRT(Inputs!$B$4) -> 2.6870058 | L16: =1.86*J16 -> 0.558 | M16: =IF(AND(L16<=Inputs!$B$11,K16>=Inputs!$B$28),1,0) -> 1 | N16: =IF(AND(L16<=Inputs!$B$12,K16>=Inputs!$B$28),1,0) -> 1 | O16: =C16/(Inputs!$B$25*D16^2/(2*PI())) -> 0.026613066 | P16: =Inputs!$B$20*60/SQRT(Inputs!$B$4)+1 -> 26.455844 | Q16: Tp sensitivity – longer-period extreme
... A18: SC2 | B18: Short-crested extreme | C18: 12.4 | D18: 16 | E18: 2 | F18: cos-2s, s=15 | G18: 2 | H18: N | I18: N | J18: =C18/Inputs!$B$4 -> 0.248 | K18: =D18/SQRT(Inputs!$B$4) -> 2.2627417 | L18: =1.86*J18 -> 0.46128 | M18: =IF(AND(L18<=Inputs!$B$11,K18>=Inputs!$B$28),1,0) -> 1 | N18: =IF(AND(L18<=Inputs!$B$12,K18>=Inputs!$B$28),1,0) -> 1 | O18: =C18/(Inputs!$B$25*D18^2/(2*PI())) -> 0.031023628 | P18: =Inputs!$B$20*60/SQRT(Inputs!$B$4)+1 -> 26.455844 | Q18: DWB only – directional extreme (run via config P3-F)
A20: Hmax ≈ 1.86·Hs (Rayleigh, ~1000 waves). Hs/Lp above ~1/15 is unrealistically steep.
A21: Wave climate is trending upward in the PNW (~0.015 m/yr mean; ~0.071 m/yr for the largest storms, Ruggiero et al. 2010) – consider a margin on the 100-yr Hs for design life.
A22: NDBC 46005 is several hundred km offshore; conditions ~200 mi W of Seattle are similar but a site-specific hindcast should replace these values before final design.

Sheet Configurations
A1: Test Configurations by Phase
A2: Each row = one model configuration. Full matrix on baselines; reduced sets on variants. Run counts and tank time are computed.
A4: Phase | B4: Config ID | C4: Description | D4: Facility (LWF/DWB) | E4: Wave headings | F4: Regular set | G4: Irregular set | H4: Decay DOFs | I4: Special runs | J4: Decay runs | K4: Regular runs | L4: Irregular runs | M4: Total runs | N4: Tank hours | O4: Notes
A5: 1 | B5: P1-A | C5: Single spar, vertical, baseline (no fins) | D5: LWF | E5: 1 | F5: Full | G5: Full | H5: 3 | I5: 0 | J5: =H5*Inputs!$B$22 -> 9 | K5: =IF(F5="None",0,E5*SUMPRODUCT((IF(F5="Full",Regular_Waves!$Q$5:$Q$26,Regular_Waves!$R$5:$R$26)="Y")*IF(D5="LWF",Regular_Waves!$O$5:$O$26,Regular_Waves!$P$5:$P$26))) -> 57 | L5: =IF(G5="None",0,E5*SUMPRODUCT((IF(G5="Full",Irregular_Seas!$H$5:$H$18,Irregular_Seas!$I$5:$I$18)="Y")*IF(D5="LWF",Irregular_Seas!$M$5:$M$18,Irregular_Seas!$N$5:$N$18)*Irregular_Seas!$G$5:$G$18)) -> 20 | M5: =J5+K5+L5+I5 -> 86 | N5: =(J5*(Inputs!$B$21+IF(D5="LWF",Inputs!$B$18,Inputs!$B$19))+I5*(Inputs!$B$23+IF(D5="LWF",Inputs!$B$18,Inputs!$B$19))+IF(F5="None",0,E5*SUMPRODUCT((IF(F5="Full",Regular_Waves!$Q$5:$Q$26,Regular_Waves!$R$5:$R$26)="Y")*IF(D5="LWF",Regular_Waves!$O$5:$O$26,Regular_Waves!$P$5:$P$26)*(Regular_Waves!$S$5:$S$26+IF(D5="LWF",Inputs!$B$18,Inputs!$B$19))))+IF(G5="None",0,E5*SUMPRODUCT((IF(G5="Full",Irregular_Seas!$H$5:$H$18,Irregular_Seas!$I$5:$I$18)="Y")*IF(D5="LWF",Irregular_Seas!$M$5:$M$18,Irregular_Seas!$N$5:$N$18)*Irregular_Seas!$G$5:$G$18*(Irregular_Seas!$P$5:$P$18+IF(D5="LWF",Inputs!$B$18,Inputs!$B$19)))))/60 -> 19.453503 | O5: Heave, pitch, surge decay
A6: 1 | B6: P1-B | C6: Single spar, vertical, damping fins | D6: LWF | E6: 1 | F6: Reduced | G6: Reduced | H6: 3 | I6: 0 | J6: =H6*Inputs!$B$22 -> 9 | K6: =IF(F6="None",0,E6*SUMPRODUCT((IF(F6="Full",Regular_Waves!$Q$5:$Q$26,Regular_Waves!$R$5:$R$26)="Y")*IF(D6="LWF",Regular_Waves!$O$5:$O$26,Regular_Waves!$P$5:$P$26))) -> 18 | L6: =IF(G6="None",0,E6*SUMPRODUCT((IF(G6="Full",Irregular_Seas!$H$5:$H$18,Irregular_Seas!$I$5:$I$18)="Y")*IF(D6="LWF",Irregular_Seas!$M$5:$M$18,Irregular_Seas!$N$5:$N$18)*Irregular_Seas!$G$5:$G$18)) -> 5 | M6: =J6+K6+L6+I6 -> 32 | N6: =(J6*(Inputs!$B$21+IF(D6="LWF",Inputs!$B$18,Inputs!$B$19))+I6*(Inputs!$B$23+IF(D6="LWF",Inputs!$B$18,Inputs!$B$19))+IF(F6="None",0,E6*SUMPRODUCT((IF(F6="Full",Regular_Waves!$Q$5:$Q$26,Regular_Waves!$R$5:$R$26)="Y")*IF(D6="LWF",Regular_Waves!$O$5:$O$26,Regular_Waves!$P$5:$P$26)*(Regular_Waves!$S$5:$S$26+IF(D6="LWF",Inputs!$B$18,Inputs!$B$19))))+IF(G6="None",0,E6*SUMPRODUCT((IF(G6="Full",Irregular_Seas!$H$5:$H$18,Irregular_Seas!$I$5:$I$18)="Y")*IF(D6="LWF",Irregular_Seas!$M$5:$M$18,Irregular_Seas!$N$5:$N$18)*Irregular_Seas!$G$5:$G$18*(Irregular_Seas!$P$5:$P$18+IF(D6="LWF",Inputs!$B$18,Inputs!$B$19)))))/60 -> 6.2521411 | O6: Fin effectiveness vs P1-A
A7: 1 | B7: P1-C | C7: Single spar, horizontal (transport) | D7: LWF | E7: 1 | F7: Reduced | G7: None | H7: 3 | I7: 12 | J7: =H7*Inputs!$B$22 -> 9 | K7: =IF(F7="None",0,E7*SUMPRODUCT((IF(F7="Full",Regular_Waves!$Q$5:$Q$26,Regular_Waves!$R$5:$R$26)="Y")*IF(D7="LWF",Regular_Waves!$O$5:$O$26,Regular_Waves!$P$5:$P$26))) -> 18 | L7: =IF(G7="None",0,E7*SUMPRODUCT((IF(G7="Full",Irregular_Seas!$H$5:$H$18,Irregular_Seas!$I$5:$I$18)="Y")*IF(D7="LWF",Irregular_Seas!$M$5:$M$18,Irregular_Seas!$N$5:$N$18)*Irregular_Seas!$G$5:$G$18)) -> 0 | M7: =J7+K7+L7+I7 -> 39 | N7: =(J7*(Inputs!$B$21+IF(D7="LWF",Inputs!$B$18,Inputs!$B$19))+I7*(Inputs!$B$23+IF(D7="LWF",Inputs!$B$18,Inputs!$B$19))+IF(F7="None",0,E7*SUMPRODUCT((IF(F7="Full",Regular_Waves!$Q$5:$Q$26,Regular_Waves!$R$5:$R$26)="Y")*IF(D7="LWF",Regular_Waves!$O$5:$O$26,Regular_Waves!$P$5:$P$26)*(Regular_Waves!$S$5:$S$26+IF(D7="LWF",Inputs!$B$18,Inputs!$B$19))))+IF(G7="None",0,E7*SUMPRODUCT((IF(G7="Full",Irregular_Seas!$H$5:$H$18,Irregular_Seas!$I$5:$I$18)="Y")*IF(D7="LWF",Irregular_Seas!$M$5:$M$18,Irregular_Seas!$N$5:$N$18)*Irregular_Seas!$G$5:$G$18*(Irregular_Seas!$P$5:$P$18+IF(D7="LWF",Inputs!$B$18,Inputs!$B$19)))))/60 -> 5.7474874 | O7: Special: tow at 4 speeds × 3 repeats (see Inputs tow table)
A8: 1 | B8: P1-D | C8: Single spar, ballast transition H→V | D8: LWF | E8: 1 | F8: None | G8: None | H8: 0 | I8: 9 | J8: =H8*Inputs!$B$22 -> 0 | K8: =IF(F8="None",0,E8*SUMPRODUCT((IF(F8="Full",Regular_Waves!$Q$5:$Q$26,Regular_Waves!$R$5:$R$26)="Y")*IF(D8="LWF",Regular_Waves!$O$5:$O$26,Regular_Waves!$P$5:$P$26))) -> 0 | L8: =IF(G8="None",0,E8*SUMPRODUCT((IF(G8="Full",Irregular_Seas!$H$5:$H$18,Irregular_Seas!$I$5:$I$18)="Y")*IF(D8="LWF",Irregular_Seas!$M$5:$M$18,Irregular_Seas!$N$5:$N$18)*Irregular_Seas!$G$5:$G$18)) -> 0 | M8: =J8+K8+L8+I8 -> 9 | N8: =(J8*(Inputs!$B$21+IF(D8="LWF",Inputs!$B$18,Inputs!$B$19))+I8*(Inputs!$B$23+IF(D8="LWF",Inputs!$B$18,Inputs!$B$19))+IF(F8="None",0,E8*SUMPRODUCT((IF(F8="Full",Regular_Waves!$Q$5:$Q$26,Regular_Waves!$R$5:$R$26)="Y")*IF(D8="LWF",Regular_Waves!$O$5:$O$26,Regular_Waves!$P$5:$P$26)*(Regular_Waves!$S$5:$S$26+IF(D8="LWF",Inputs!$B$18,Inputs!$B$19))))+IF(G8="None",0,E8*SUMPRODUCT((IF(G8="Full",Irregular_Seas!$H$5:$H$18,Irregular_Seas!$I$5:$I$18)="Y")*IF(D8="LWF",Irregular_Seas!$M$5:$M$18,Irregular_Seas!$N$5:$N$18)*Irregular_Seas!$G$5:$G$18*(Irregular_Seas!$P$5:$P$18+IF(D8="LWF",Inputs!$B$18,Inputs!$B$19)))))/60 -> 1.65 | O8: Special: transition in calm + O1 + O2, 3 repeats each
